Workbook

Sheet Calcs
J4: Supply fan power allowances = 1, Otherwise = 0 | K4: 0 | L4: 0 | M4: 0 | N4: 1 | O4: 1 | P4: 0 | Q4: 0 | R4: 1 | S4: 0 | T4: 0 | U4: 1 | V4: 1 | W4: 0
K5: Return or exhaust systems required by code or accreditation standards to be fully ducted, or systems required to maintain air pressure differentials between adjacent rooms | L5: Return or exhaust systems required by code or accreditation standards to be fully ducted, or systems required to maintain air pressure differentials between adjacent rooms | M5: Exhaust filters, scrubbers, or other exhaust treatment required by code or standard. Value shown is allowed w/cfm per 1.0 in. wg air pressure drop. [Calculation required, see note 4] | N5: Filtration Allowance for > Merv 16 or HEPA Filter (two times the clean filter pressure dropmid-life) 2 | O5: Allowance for gas phase filtration required by code or accredited standard. Value shown is allowed w/cfm per 1.0 in. wg air pressure drop. [Calculation required, see note 4] | P5: Biosafety cabinet. Value shown is allowed w/cfm per 1.0 in. wg air pressure drop. [Calculation required, see note 4] | Q5: Exhaust System Base Allowance | R5: Energy Recovery Allowance for 0.60 ≤ ERR <0.65 | S5: Energy Recovery Allowance for 0.60 ≤ ERR <0.65 | T5: Filter (any MERV value)2 | U5: Low-turndown single-zone VAV fan systems meeting the requirements in note 7. | V5: Coil Runaround Loop | W5: Coil Runaround Loop
I6: SysType | J6: FlowCap | K6: Exhaust systems required by code to be fully ducted | L6: Return systems required by code to be fully ducted | M6: Exhaust filters, scrubbers, or other exhaust treatment (calculation required, see note) | N6: Particulate filtration credit: MERV 16 or greater and electronically enhanced filters | O6: Carbon and other gas-phase air cleaners (calculation required, see note) | P6: Biosafety cabinet (calculation required, see note) | Q6: Exhaust Systems Base Allowance | R6: Supply - Energy Recovery (Enthalpy Recovery Ratio ? 0.60 and <0.65) | S6: Return - Energy Recovery (Enthalpy Recovery Ratio ? 0.60 and <0.65) | T6: Return - Filter (any MERV value) | U6: Single Zone VAV Systems that are capable of turning down to 50% of full load airflow at a maximum of 30% design wattage | V6: Supply -Coil Runaround Loop | W6: Return - Coil Runaround Loop
I7: MultiZoneVAV | J7: ≤5,000 cfm | K7: =IF(K$4=1,_xlfn.XLOOKUP(K$5,$B$20:$B$46,$C$20:$C$46),_xlfn.XLOOKUP(K$5,$B$59:$B$75,$C$59:$C$75)) -> 0.116 | L7: =IF(L$4=1,_xlfn.XLOOKUP(L$5,$B$20:$B$46,$C$20:$C$46),_xlfn.XLOOKUP(L$5,$B$59:$B$75,$C$59:$C$75)) -> 0.116 | M7: =IF(M$4=1,_xlfn.XLOOKUP(M$5,$B$20:$B$46,$C$20:$C$46),_xlfn.XLOOKUP(M$5,$B$59:$B$75,$C$59:$C$75)) -> 0.231 | N7: =IF(N$4=1,_xlfn.XLOOKUP(N$5,$B$20:$B$46,$C$20:$C$46),_xlfn.XLOOKUP(N$5,$B$59:$B$75,$C$59:$C$75)) -> 0.335 | O7: =IF(O$4=1,_xlfn.XLOOKUP(O$5,$B$20:$B$46,$C$20:$C$46),_xlfn.XLOOKUP(O$5,$B$59:$B$75,$C$59:$C$75)) -> 0.224 | P7: =IF(P$4=1,_xlfn.XLOOKUP(P$5,$B$20:$B$46,$C$20:$C$46),_xlfn.XLOOKUP(P$5,$B$59:$B$75,$C$59:$C$75)) -> 0.231 | Q7: =IF(Q$4=1,_xlfn.XLOOKUP(Q$5,$B$20:$B$46,$C$20:$C$46),_xlfn.XLOOKUP(Q$5,$B$59:$B$75,$C$59:$C$75)) -> 0.221 | R7: =IF(R$4=1,_xlfn.XLOOKUP(R$5,$B$20:$B$46,$C$20:$C$46),_xlfn.XLOOKUP(R$5,$B$59:$B$75,$C$59:$C$75)) -> 0.184 | ... W7: =IF(W$4=1,_xlfn.XLOOKUP(W$5,$B$20:$B$46,$C$20:$C$46),_xlfn.XLOOKUP(W$5,$B$59:$B$75,$C$59:$C$75)) -> 0.139
I8: MultiZoneVAV | J8: >5,000 and ≤10,000 cfm | K8: =IF(K$4=1,_xlfn.XLOOKUP(K$5,$B$20:$B$46,$D$20:$D$46),_xlfn.XLOOKUP(K$5,$B$59:$B$75,$D$59:$D$75)) -> 0.1 | L8: =IF(L$4=1,_xlfn.XLOOKUP(L$5,$B$20:$B$46,$D$20:$D$46),_xlfn.XLOOKUP(L$5,$B$59:$B$75,$D$59:$D$75)) -> 0.1 | M8: =IF(M$4=1,_xlfn.XLOOKUP(M$5,$B$20:$B$46,$D$20:$D$46),_xlfn.XLOOKUP(M$5,$B$59:$B$75,$D$59:$D$75)) -> 0.198 | N8: =IF(N$4=1,_xlfn.XLOOKUP(N$5,$B$20:$B$46,$D$20:$D$46),_xlfn.XLOOKUP(N$5,$B$59:$B$75,$D$59:$D$75)) -> 0.28 | O8: =IF(O$4=1,_xlfn.XLOOKUP(O$5,$B$20:$B$46,$D$20:$D$46),_xlfn.XLOOKUP(O$5,$B$59:$B$75,$D$59:$D$75)) -> 0.188 | P8: =IF(P$4=1,_xlfn.XLOOKUP(P$5,$B$20:$B$46,$D$20:$D$46),_xlfn.XLOOKUP(P$5,$B$59:$B$75,$D$59:$D$75)) -> 0.198 | Q8: =IF(Q$4=1,_xlfn.XLOOKUP(Q$5,$B$20:$B$46,$D$20:$D$46),_xlfn.XLOOKUP(Q$5,$B$59:$B$75,$D$59:$D$75)) -> 0.246 | R8: =IF(R$4=1,_xlfn.XLOOKUP(R$5,$B$20:$B$46,$D$20:$D$46),_xlfn.XLOOKUP(R$5,$B$59:$B$75,$D$59:$D$75)) -> 0.155 | ... W8: =IF(W$4=1,_xlfn.XLOOKUP(W$5,$B$20:$B$46,$D$20:$D$46),_xlfn.XLOOKUP(W$5,$B$59:$B$75,$D$59:$D$75)) -> 0.12
I9: MultiZoneVAV | J9: >10,000 cfm | K9: =IF(K$4=1,_xlfn.XLOOKUP(K$5,$B$20:$B$46,$E$20:$E$46),_xlfn.XLOOKUP(K$5,$B$59:$B$75,$E$59:$E$75)) -> 0.089 | L9: =IF(L$4=1,_xlfn.XLOOKUP(L$5,$B$20:$B$46,$E$20:$E$46),_xlfn.XLOOKUP(L$5,$B$59:$B$75,$E$59:$E$75)) -> 0.089 | M9: =IF(M$4=1,_xlfn.XLOOKUP(M$5,$B$20:$B$46,$E$20:$E$46),_xlfn.XLOOKUP(M$5,$B$59:$B$75,$E$59:$E$75)) -> 0.177 | N9: =IF(N$4=1,_xlfn.XLOOKUP(N$5,$B$20:$B$46,$E$20:$E$46),_xlfn.XLOOKUP(N$5,$B$59:$B$75,$E$59:$E$75)) -> 0.265 | O9: =IF(O$4=1,_xlfn.XLOOKUP(O$5,$B$20:$B$46,$E$20:$E$46),_xlfn.XLOOKUP(O$5,$B$59:$B$75,$E$59:$E$75)) -> 0.176 | P9: =IF(P$4=1,_xlfn.XLOOKUP(P$5,$B$20:$B$46,$E$20:$E$46),_xlfn.XLOOKUP(P$5,$B$59:$B$75,$E$59:$E$75)) -> 0.177 | Q9: =IF(Q$4=1,_xlfn.XLOOKUP(Q$5,$B$20:$B$46,$E$20:$E$46),_xlfn.XLOOKUP(Q$5,$B$59:$B$75,$E$59:$E$75)) -> 0.236 | R9: =IF(R$4=1,_xlfn.XLOOKUP(R$5,$B$20:$B$46,$E$20:$E$46),_xlfn.XLOOKUP(R$5,$B$59:$B$75,$E$59:$E$75)) -> 0.144 | ... W9: =IF(W$4=1,_xlfn.XLOOKUP(W$5,$B$20:$B$46,$E$20:$E$46),_xlfn.XLOOKUP(W$5,$B$59:$B$75,$E$59:$E$75)) -> 0.107
I10: AllOther | J10: ≤5,000 cfm | K10: =IF(K$4=1,_xlfn.XLOOKUP(K$5,$B$20:$B$46,$F$20:$F$46),_xlfn.XLOOKUP(K$5,$B$59:$B$75,$F$59:$F$75)) -> 0.116 | L10: =IF(L$4=1,_xlfn.XLOOKUP(L$5,$B$20:$B$46,$F$20:$F$46),_xlfn.XLOOKUP(L$5,$B$59:$B$75,$F$59:$F$75)) -> 0.116 | M10: =IF(M$4=1,_xlfn.XLOOKUP(M$5,$B$20:$B$46,$F$20:$F$46),_xlfn.XLOOKUP(M$5,$B$59:$B$75,$F$59:$F$75)) -> 0.232 | N10: =IF(N$4=1,_xlfn.XLOOKUP(N$5,$B$20:$B$46,$F$20:$F$46),_xlfn.XLOOKUP(N$5,$B$59:$B$75,$F$59:$F$75)) -> 0.342 | O10: =IF(O$4=1,_xlfn.XLOOKUP(O$5,$B$20:$B$46,$F$20:$F$46),_xlfn.XLOOKUP(O$5,$B$59:$B$75,$F$59:$F$75)) -> 0.231 | P10: =IF(P$4=1,_xlfn.XLOOKUP(P$5,$B$20:$B$46,$F$20:$F$46),_xlfn.XLOOKUP(P$5,$B$59:$B$75,$F$59:$F$75)) -> 0.232 | Q10: =IF(Q$4=1,_xlfn.XLOOKUP(Q$5,$B$20:$B$46,$F$20:$F$46),_xlfn.XLOOKUP(Q$5,$B$59:$B$75,$F$59:$F$75)) -> 0.186 | R10: =IF(R$4=1,_xlfn.XLOOKUP(R$5,$B$20:$B$46,$F$20:$F$46),_xlfn.XLOOKUP(R$5,$B$59:$B$75,$F$59:$F$75)) -> 0.19 | ... W10: =IF(W$4=1,_xlfn.XLOOKUP(W$5,$B$20:$B$46,$F$20:$F$46),_xlfn.XLOOKUP(W$5,$B$59:$B$75,$F$59:$F$75)) -> 0.139
I11: AllOther | J11: >5,000 and ≤10,000 cfm | K11: =IF(K$4=1,_xlfn.XLOOKUP(K$5,$B$20:$B$46,$G$20:$G$46),_xlfn.XLOOKUP(K$5,$B$59:$B$75,$G$59:$G$75)) -> 0.102 | L11: =IF(L$4=1,_xlfn.XLOOKUP(L$5,$B$20:$B$46,$G$20:$G$46),_xlfn.XLOOKUP(L$5,$B$59:$B$75,$G$59:$G$75)) -> 0.102 | M11: =IF(M$4=1,_xlfn.XLOOKUP(M$5,$B$20:$B$46,$G$20:$G$46),_xlfn.XLOOKUP(M$5,$B$59:$B$75,$G$59:$G$75)) -> 0.202 | N11: =IF(N$4=1,_xlfn.XLOOKUP(N$5,$B$20:$B$46,$G$20:$G$46),_xlfn.XLOOKUP(N$5,$B$59:$B$75,$G$59:$G$75)) -> 0.292 | O11: =IF(O$4=1,_xlfn.XLOOKUP(O$5,$B$20:$B$46,$G$20:$G$46),_xlfn.XLOOKUP(O$5,$B$59:$B$75,$G$59:$G$75)) -> 0.197 | P11: =IF(P$4=1,_xlfn.XLOOKUP(P$5,$B$20:$B$46,$G$20:$G$46),_xlfn.XLOOKUP(P$5,$B$59:$B$75,$G$59:$G$75)) -> 0.202 | Q11: =IF(Q$4=1,_xlfn.XLOOKUP(Q$5,$B$20:$B$46,$G$20:$G$46),_xlfn.XLOOKUP(Q$5,$B$59:$B$75,$G$59:$G$75)) -> 0.184 | R11: =IF(R$4=1,_xlfn.XLOOKUP(R$5,$B$20:$B$46,$G$20:$G$46),_xlfn.XLOOKUP(R$5,$B$59:$B$75,$G$59:$G$75)) -> 0.163 | ... W11: =IF(W$4=1,_xlfn.XLOOKUP(W$5,$B$20:$B$46,$G$20:$G$46),_xlfn.XLOOKUP(W$5,$B$59:$B$75,$G$59:$G$75)) -> 0.123
I12: AllOther | J12: >10,000 cfm | K12: =IF(K$4=1,_xlfn.XLOOKUP(K$5,$B$20:$B$46,$H$20:$H$46),_xlfn.XLOOKUP(K$5,$B$59:$B$75,$H$59:$H$75)) -> 0.091 | L12: =IF(L$4=1,_xlfn.XLOOKUP(L$5,$B$20:$B$46,$H$20:$H$46),_xlfn.XLOOKUP(L$5,$B$59:$B$75,$H$59:$H$75)) -> 0.091 | M12: =IF(M$4=1,_xlfn.XLOOKUP(M$5,$B$20:$B$46,$H$20:$H$46),_xlfn.XLOOKUP(M$5,$B$59:$B$75,$H$59:$H$75)) -> 0.179 | N12: =IF(N$4=1,_xlfn.XLOOKUP(N$5,$B$20:$B$46,$H$20:$H$46),_xlfn.XLOOKUP(N$5,$B$59:$B$75,$H$59:$H$75)) -> 0.264 | O12: =IF(O$4=1,_xlfn.XLOOKUP(O$5,$B$20:$B$46,$H$20:$H$46),_xlfn.XLOOKUP(O$5,$B$59:$B$75,$H$59:$H$75)) -> 0.177 | P12: =IF(P$4=1,_xlfn.XLOOKUP(P$5,$B$20:$B$46,$H$20:$H$46),_xlfn.XLOOKUP(P$5,$B$59:$B$75,$H$59:$H$75)) -> 0.179 | Q12: =IF(Q$4=1,_xlfn.XLOOKUP(Q$5,$B$20:$B$46,$H$20:$H$46),_xlfn.XLOOKUP(Q$5,$B$59:$B$75,$H$59:$H$75)) -> 0.19 | R12: =IF(R$4=1,_xlfn.XLOOKUP(R$5,$B$20:$B$46,$H$20:$H$46),_xlfn.XLOOKUP(R$5,$B$59:$B$75,$H$59:$H$75)) -> 0.146 | ... W12: =IF(W$4=1,_xlfn.XLOOKUP(W$5,$B$20:$B$46,$H$20:$H$46),_xlfn.XLOOKUP(W$5,$B$59:$B$75,$H$59:$H$75)) -> 0.109
V13: As SZSys | W13: As MZSys
J14: Calculated Values | K14: 3a - SZAC | L14: 3b - SZHP (no furnace) | M14: 3c - SZHP (with furnace) | N14: 7a - SZVAVAC | O14: 7b - SZVAVHP (no furnace) | P14: 7c - SZVAVHP (with furnace) | Q14: 5 - PVAV | R14: 6 - VAV | S14: 9 - HEATVENT | T14: 13a - BKICHMAU | U14: 13b - PKITCHMAU | V14: 14 - 4PSZVAV | W14: 14 - 4PSZVAV | X14: 15 - PVAVAWHP | AA14: From CEC in an email, dated 7/5/2023
J15: ≤5,000 cfm | K15: =IF(K19<>"",SUMIF(K20:K75,"x",OFFSET($B$20,0,1,56,1)),SUMIF(K20:K75,"x",OFFSET($B$20,0,4,56,1))) -> 0.8 | L15: =IF(L19<>"",SUMIF(L20:L75,"x",OFFSET($B$20,0,1,56,1)),SUMIF(L20:L75,"x",OFFSET($B$20,0,4,56,1))) -> 0.742 | M15: =IF(M19<>"",SUMIF(M20:M75,"x",OFFSET($B$20,0,1,56,1)),SUMIF(M20:M75,"x",OFFSET($B$20,0,4,56,1))) -> 0.8 | N15: =IF(N19<>"",SUMIF(N20:N75,"x",OFFSET($B$20,0,1,56,1)),SUMIF(N20:N75,"x",OFFSET($B$20,0,4,56,1))) -> 0.8 | O15: =IF(O19<>"",SUMIF(O20:O75,"x",OFFSET($B$20,0,1,56,1)),SUMIF(O20:O75,"x",OFFSET($B$20,0,4,56,1))) -> 0.742 | P15: =IF(P19<>"",SUMIF(P20:P75,"x",OFFSET($B$20,0,1,56,1)),SUMIF(P20:P75,"x",OFFSET($B$20,0,4,56,1))) -> 0.8 | Q15: =IF(Q19<>"",SUMIF(Q20:Q75,"x",OFFSET($B$20,0,1,56,1)),SUMIF(Q20:Q75,"x",OFFSET($B$20,0,4,56,1))) -> 0.978 | R15: =IF(R19<>"",SUMIF(R20:R75,"x",OFFSET($B$20,0,1,56,1)),SUMIF(R20:R75,"x",OFFSET($B$20,0,4,56,1))) -> 0.978 | ... X15: =IF(X19<>"",SUMIF(X20:X75,"x",OFFSET($B$20,0,1,56,1)),SUMIF(X20:X75,"x",OFFSET($B$20,0,4,56,1))) -> 0.978
J16: >5,000 and ≤10,000 cfm | K16: =IF(K19<>"",SUMIF(K20:K75,"x",OFFSET($B$20,0,2,56,1)),SUMIF(K20:K75,"x",OFFSET($B$20,0,5,56,1))) -> 0.78 | L16: =IF(L19<>"",SUMIF(L20:L75,"x",OFFSET($B$20,0,2,56,1)),SUMIF(L20:L75,"x",OFFSET($B$20,0,5,56,1))) -> 0.72 | M16: =IF(M19<>"",SUMIF(M20:M75,"x",OFFSET($B$20,0,2,56,1)),SUMIF(M20:M75,"x",OFFSET($B$20,0,5,56,1))) -> 0.78 | N16: =IF(N19<>"",SUMIF(N20:N75,"x",OFFSET($B$20,0,2,56,1)),SUMIF(N20:N75,"x",OFFSET($B$20,0,5,56,1))) -> 0.78 | O16: =IF(O19<>"",SUMIF(O20:O75,"x",OFFSET($B$20,0,2,56,1)),SUMIF(O20:O75,"x",OFFSET($B$20,0,5,56,1))) -> 0.72 | P16: =IF(P19<>"",SUMIF(P20:P75,"x",OFFSET($B$20,0,2,56,1)),SUMIF(P20:P75,"x",OFFSET($B$20,0,5,56,1))) -> 0.78 | Q16: =IF(Q19<>"",SUMIF(Q20:Q75,"x",OFFSET($B$20,0,2,56,1)),SUMIF(Q20:Q75,"x",OFFSET($B$20,0,5,56,1))) -> 1.013 | R16: =IF(R19<>"",SUMIF(R20:R75,"x",OFFSET($B$20,0,2,56,1)),SUMIF(R20:R75,"x",OFFSET($B$20,0,5,56,1))) -> 1.013 | ... X16: =IF(X19<>"",SUMIF(X20:X75,"x",OFFSET($B$20,0,2,56,1)),SUMIF(X20:X75,"x",OFFSET($B$20,0,5,56,1))) -> 1.013
A17: TABLE 140.4-A: Supply Fan Power Allowances (watts/cfm) | J17: >10,000 cfm | K17: =IF(K19<>"",SUMIF(K20:K75,"x",OFFSET($B$20,0,3,56,1)),SUMIF(K20:K75,"x",OFFSET($B$20,0,6,56,1))) -> 0.748 | L17: =IF(L19<>"",SUMIF(L20:L75,"x",OFFSET($B$20,0,3,56,1)),SUMIF(L20:L75,"x",OFFSET($B$20,0,6,56,1))) -> 0.676 | M17: =IF(M19<>"",SUMIF(M20:M75,"x",OFFSET($B$20,0,3,56,1)),SUMIF(M20:M75,"x",OFFSET($B$20,0,6,56,1))) -> 0.748 | N17: =IF(N19<>"",SUMIF(N20:N75,"x",OFFSET($B$20,0,3,56,1)),SUMIF(N20:N75,"x",OFFSET($B$20,0,6,56,1))) -> 0.748 | O17: =IF(O19<>"",SUMIF(O20:O75,"x",OFFSET($B$20,0,3,56,1)),SUMIF(O20:O75,"x",OFFSET($B$20,0,6,56,1))) -> 0.676 | P17: =IF(P19<>"",SUMIF(P20:P75,"x",OFFSET($B$20,0,3,56,1)),SUMIF(P20:P75,"x",OFFSET($B$20,0,6,56,1))) -> 0.748 | Q17: =IF(Q19<>"",SUMIF(Q20:Q75,"x",OFFSET($B$20,0,3,56,1)),SUMIF(Q20:Q75,"x",OFFSET($B$20,0,6,56,1))) -> 0.946 | R17: =IF(R19<>"",SUMIF(R20:R75,"x",OFFSET($B$20,0,3,56,1)),SUMIF(R20:R75,"x",OFFSET($B$20,0,6,56,1))) -> 0.946 | ... X17: =IF(X19<>"",SUMIF(X20:X75,"x",OFFSET($B$20,0,3,56,1)),SUMIF(X20:X75,"x",OFFSET($B$20,0,6,56,1))) -> 0.946
A19: x | C19: Multi-Zone VAV Systems ≤5,000 cfm | D19: Multi-Zone VAV Systems >5,000 and ≤10,000 cfm | E19: Multi-Zone VAV Systems >10,000 cfm | F19: All Other Fan Systems ≤5,000 cfm | G19: All Other Fan Systems >5,000 and ≤10,000 cfm | H19: All Other Fan Systems >10,000 cfm | J19: Is Multi-Zone System? | Q19: x | R19: x | W19: x | X19: x | Y19: =COUNTIF(K19:X19,"x") -> 4
A20: x | B20: Supply System Base Allowance for AHU Serving Spaces < 6 Floors Away. | C20: 0.395 | D20: 0.453 | E20: 0.413 | F20: 0.232 | G20: 0.256 | H20: 0.236 | J20: =B20 -> Supply System Base Allowance for AHU Serving Spaces < 6 Floors Away. | K20: x | L20: x | M20: x | N20: x | O20: x | P20: x | Q20: x | R20: x | S20: x | T20: x | U20: x | V20: x | W20: x | X20: x | Y20: =COUNTIF(K20:X20,"x") -> 14
A21: x | B21: Supply System Base Allowance for AHU Serving Spaces > 6 Floors Away | C21: 0.508 | D21: 0.548 | E21: 0.501 | F21: 0.349 | G21: 0.356 | H21: 0.325 | J21: =B21 -> Supply System Base Allowance for AHU Serving Spaces > 6 Floors Away | Y21: =COUNTIF(K21:X21,"x") -> 0
A22: x | B22: MERV 13 to MERV 16 Filter Upstream of Thermal Conditioning Equipment (two times the clean filter pressure dropmid-life)2 | C22: 0.136 | D22: 0.114 | E22: 0.105 | F22: 0.139 | G22: 0.12 | H22: 0.107 | J22: =B22 -> MERV 13 to MERV 16 Filter Upstream of Thermal Conditioning Equipment (two times the clean filter pressure dropmid-life)2 | K22: x | L22: x | M22: x | N22: x | O22: x | P22: x | Q22: x | R22: x | S22: x | T22: x | U22: x | V22: x | W22: x | X22: x | Y22: =COUNTIF(K22:X22,"x") -> 14
A23: x | B23: MERV 13 to MERV 16 Final Filter Downstream of Thermal Conditioning Equipment. (two times the clean filter pressure dropmid-life) 2 | C23: 0.225 | D23: 0.188 | E23: 0.176 | F23: 0.231 | G23: 0.197 | H23: 0.177 | J23: =B23 -> MERV 13 to MERV 16 Final Filter Downstream of Thermal Conditioning Equipment. (two times the clean filter pressure dropmid-life) 2 | Y23: =COUNTIF(K23:X23,"x") -> 0
A24: x | B24: Filtration Allowance for > Merv 16 or HEPA Filter (two times the clean filter pressure dropmid-life) 2 | C24: 0.335 | D24: 0.28 | E24: 0.265 | F24: 0.342 | G24: 0.292 | H24: 0.264 | J24: =B24 -> Filtration Allowance for > Merv 16 or HEPA Filter (two times the clean filter pressure dropmid-life) 2 | Y24: =COUNTIF(K24:X24,"x") -> 0
A25: x | B25: Central Hydronic Heating Coil Allowance | C25: 0.046 | D25: 0.048 | E25: 0.052 | F25: 0.046 | G25: 0.05 | H25: 0.054 | J25: =B25 -> Central Hydronic Heating Coil Allowance | Q25: x | R25: x | T25: x | V25: x | W25: x | X25: x | Y25: =COUNTIF(K25:X25,"x") -> 6
A26: x | B26: Electric Heat Allowance | C26: 0.046 | D26: 0.038 | E26: 0.035 | F26: 0.046 | G26: 0.04 | H26: 0.036 | J26: =B26 -> Electric Heat Allowance | Y26: =COUNTIF(K26:X26,"x")+1 -> 1
A27: x | B27: Gas Heat Allowance | C27: 0.069 | D27: 0.057 | E27: 0.07 | F27: 0.058 | G27: 0.06 | H27: 0.072 | J27: =B27 -> Gas Heat Allowance | K27: x | M27: x | N27: x | P27: x | S27: x | U27: x | Y27: =COUNTIF(K27:X27,"x") -> 6
A28: x | B28: Hydronic/DX Cooling Coil, or Heat Pump Coil (wet) Allowance | C28: 0.135 | D28: 0.114 | E28: 0.105 | F28: 0.139 | G28: 0.12 | H28: 0.107 | J28: =B28 -> Hydronic/DX Cooling Coil, or Heat Pump Coil (wet) Allowance | K28: x | L28: x | M28: x | N28: x | O28: x | P28: x | Q28: x | R28: x | T28: x | U28: x | V28: x | W28: x | X28: x | Y28: =COUNTIF(K28:X28,"x") -> 13
A29: x | B29: Solid or Liquid Desiccant System Allowance | C29: 0.157 | D29: 0.132 | E29: 0.123 | F29: 0.163 | G29: 0.139 | H29: 0.124 | J29: =B29 -> Solid or Liquid Desiccant System Allowance | Y29: =COUNTIF(K29:X29,"x") -> 0
A30: x | B30: Reheat Coil for Dehumidification Allowance | C30: 0.045 | D30: 0.038 | E30: 0.035 | F30: 0.046 | G30: 0.04 | H30: 0.036 | J30: =B30 -> Reheat Coil for Dehumidification Allowance | Y30: =COUNTIF(K30:X30,"x") -> 0
A31: x | B31: Allowance for evaporative humidifier/cooler in series with a cooling coil. Value shown is allowed watts/cfm per 1.0 in. wg. Determine pressure loss (in. wg) at 400 fpm or maximum velocity allowed by the manufacturer, whichever is less. [Calculation required, see note 4] | C31: 0.224 | D31: 0.188 | E31: 0.176 | F31: 0.231 | G31: 0.197 | H31: 0.177 | J31: =B31 -> Allowance for evaporative humidifier/cooler in series with a cooling coil. Value shown is allowed watts/cfm per 1.0 in. wg. Determine pressure loss (in. wg) at 400 fpm or maximum velocity allowed by the manufacturer, whichever is less. [Calculation required, see note 4] | Y31: =COUNTIF(K31:X31,"x") -> 0
A32: x | B32: Allowance for 100% outdoor air system meeting the requirements of Note 5. | C32: 0 | D32: 0 | E32: 0 | F32: 0.07 | G32: 0.1 | H32: 0.107 | J32: =B32 -> Allowance for 100% outdoor air system meeting the requirements of Note 5. | V32: x | W32: x | Y32: =COUNTIF(K32:X32,"x") -> 2
A33: x | B33: Energy Recovery Allowance for 0.50 ≤ ERR <0.55 | C33: 0.135 | D33: 0.114 | E33: 0.105 | F33: 0.139 | G33: 0.12 | H33: 0.107 | J33: =B33 -> Energy Recovery Allowance for 0.50 ≤ ERR <0.55 | Y33: =COUNTIF(K33:X33,"x") -> 0
A34: x | B34: Energy Recovery Allowance for 0.55 ≤ ERR <0.60 | C34: 0.16 | D34: 0.134 | E34: 0.124 | F34: 0.165 | G34: 0.141 | H34: 0.126 | J34: =B34 -> Energy Recovery Allowance for 0.55 ≤ ERR <0.60 | Y34: =COUNTIF(K34:X34,"x") -> 0
A35: x | B35: Energy Recovery Allowance for 0.60 ≤ ERR <0.65 | C35: 0.184 | D35: 0.155 | E35: 0.144 | F35: 0.19 | G35: 0.163 | H35: 0.146 | J35: =B35 -> Energy Recovery Allowance for 0.60 ≤ ERR <0.65 | Y35: =COUNTIF(K35:X35,"x")+1 -> 1
A36: x | B36: Energy Recovery Allowance for 0.65 ≤ ERR <0.70 | C36: 0.208 | D36: 0.175 | E36: 0.163 | F36: 0.215 | G36: 0.184 | H36: 0.165 | J36: =B36 -> Energy Recovery Allowance for 0.65 ≤ ERR <0.70 | Y36: =COUNTIF(K36:X36,"x") -> 0
A37: x | B37: Energy Recovery Allowance for 0.70 ≤ ERR <0.75 | C37: 0.232 | D37: 0.196 | E37: 0.183 | F37: 0.24 | G37: 0.205 | H37: 0.184 | J37: =B37 -> Energy Recovery Allowance for 0.70 ≤ ERR <0.75 | Y37: =COUNTIF(K37:X37,"x") -> 0
A38: x | B38: Energy Recovery Allowance for 0.75 ≤ ERR <0.80 | C38: 0.257 | D38: 0.216 | E38: 0.202 | F38: 0.264 | G38: 0.226 | H38: 0.203 | J38: =B38 -> Energy Recovery Allowance for 0.75 ≤ ERR <0.80 | Y38: =COUNTIF(K38:X38,"x") -> 0
A39: x | B39: Energy Recovery Allowance for ERR ≥ 0.80 | C39: 0.281 | D39: 0.236 | E39: 0.222 | F39: 0.289 | G39: 0.247 | H39: 0.222 | J39: =B39 -> Energy Recovery Allowance for ERR ≥ 0.80 | Y39: =COUNTIF(K39:X39,"x") -> 0
A40: x | B40: Coil Runaround Loop | C40: 0.135 | D40: 0.114 | E40: 0.105 | F40: 0.139 | G40: 0.12 | H40: 0.107 | J40: =B40 -> Coil Runaround Loop | Y40: =COUNTIF(K40:X40,"x")+1 -> 1
A41: x | B41: Allowance for gas phase filtration required by code or accredited standard. Value shown is allowed w/cfm per 1.0 in. wg air pressure drop. [Calculation required, see note 4] | C41: 0.224 | D41: 0.188 | E41: 0.176 | F41: 0.231 | G41: 0.197 | H41: 0.177 | J41: =B41 -> Allowance for gas phase filtration required by code or accredited standard. Value shown is allowed w/cfm per 1.0 in. wg air pressure drop. [Calculation required, see note 4] | Y41: =COUNTIF(K41:X41,"x") -> 0
A42: x | B42: Economizer Return Damper | C42: 0.045 | D42: 0.038 | E42: 0.035 | F42: 0.046 | G42: 0.04 | H42: 0.036 | J42: =B42 -> Economizer Return Damper | K42: x | L42: x | M42: x | N42: x | O42: x | P42: x | Q42: x | R42: x | T42: x | U42: x | X42: x | Y42: =COUNTIF(K42:X42,"x") -> 11
A43: x | B43: Air Blender Allowance | C43: 0.045 | D43: 0.038 | E43: 0.035 | F43: 0.046 | G43: 0.04 | H43: 0.036 | J43: =B43 -> Air Blender Allowance | Y43: =COUNTIF(K43:X43,"x") -> 0
A44: x | B44: Allowance for sound attenuation section [fans serving spaces with design background noise goals below NC35]. | C44: 0.034 | D44: 0.029 | E44: 0.026 | F44: 0.035 | G44: 0.03 | H44: 0.027 | J44: =B44 -> Allowance for sound attenuation section [fans serving spaces with design background noise goals below NC35]. | Y44: =COUNTIF(K44:X44,"x") -> 0
...

Sheet For CSV
A1: ;
A2: TABLE T24N_2025FanPwrIdxAdj
A3: ; | D3: Exhaust systems required by code to be fully ducted | E3: Return systems required by code to be fully ducted | F3: Exhaust filters, scrubbers, or other exhaust treatment (calculation required, see note) | G3: Particulate filtration credit: MERV 16 or greater and electronically enhanced filters | H3: Carbon and other gas-phase air cleaners (calculation required, see note) | I3: Biosafety cabinet (calculation required, see note) | J3: Exhaust Systems Base Allowance | K3: Supply - Energy Recovery (Enthalpy Recovery Ratio ? 0.60 and <0.65) | L3: Return - Energy Recovery (Enthalpy Recovery Ratio ? 0.60 and <0.65) | M3: Return - Filter (any MERV value) | N3: Single Zone VAV Systems that are capable of turning down to 50% of full load airflow at a maximum of 30% design wattage | O3: Supply -Coil Runaround Loop | P3: Return - Coil Runaround Loop
B4: SysType | C4: FlowCap | D4: FullyDuctedExh | E4: FullyDuctedRet | F4: ExhFilters | G4: MERVGTE16 | H4: GasPhaseAirCleaners | I4: BiosftyCabExh | J4: ExhBaseAllow | K4: ERVSupply | L4: ERVReturn | M4: RetFilter | N4: SZVAV | O4: ERVCoilRunaroundSupply | P4: ERVCoilRunaroundReturn
B5: MultiZoneVAV | C5: <=5000 | D5: =Calcs!K7 -> 0.116 | E5: =Calcs!L7 -> 0.116 | F5: =Calcs!M7 -> 0.231 | G5: =Calcs!N7 -> 0.335 | H5: =Calcs!O7 -> 0.224 | I5: =Calcs!P7 -> 0.231 | J5: =Calcs!Q7 -> 0.221 | K5: =Calcs!R7 -> 0.184 | ... P5: =Calcs!W7 -> 0.139
B6: MultiZoneVAV | C6: <=10000 | D6: =Calcs!K8 -> 0.1 | E6: =Calcs!L8 -> 0.1 | F6: =Calcs!M8 -> 0.198 | G6: =Calcs!N8 -> 0.28 | H6: =Calcs!O8 -> 0.188 | I6: =Calcs!P8 -> 0.198 | J6: =Calcs!Q8 -> 0.246 | K6: =Calcs!R8 -> 0.155 | ... P6: =Calcs!W8 -> 0.12
B7: MultiZoneVAV | C7: >10000 | D7: =Calcs!K9 -> 0.089 | E7: =Calcs!L9 -> 0.089 | F7: =Calcs!M9 -> 0.177 | G7: =Calcs!N9 -> 0.265 | H7: =Calcs!O9 -> 0.176 | I7: =Calcs!P9 -> 0.177 | J7: =Calcs!Q9 -> 0.236 | K7: =Calcs!R9 -> 0.144 | ... P7: =Calcs!W9 -> 0.107
B8: AllOther | C8: <=5000 | D8: =Calcs!K10 -> 0.116 | E8: =Calcs!L10 -> 0.116 | F8: =Calcs!M10 -> 0.232 | G8: =Calcs!N10 -> 0.342 | H8: =Calcs!O10 -> 0.231 | I8: =Calcs!P10 -> 0.232 | J8: =Calcs!Q10 -> 0.186 | K8: =Calcs!R10 -> 0.19 | ... P8: =Calcs!W10 -> 0.139
B9: AllOther | C9: <=10000 | D9: =Calcs!K11 -> 0.102 | E9: =Calcs!L11 -> 0.102 | F9: =Calcs!M11 -> 0.202 | G9: =Calcs!N11 -> 0.292 | H9: =Calcs!O11 -> 0.197 | I9: =Calcs!P11 -> 0.202 | J9: =Calcs!Q11 -> 0.184 | K9: =Calcs!R11 -> 0.163 | ... P9: =Calcs!W11 -> 0.123
B10: AllOther | C10: >10000 | D10: =Calcs!K12 -> 0.091 | E10: =Calcs!L12 -> 0.091 | F10: =Calcs!M12 -> 0.179 | G10: =Calcs!N12 -> 0.264 | H10: =Calcs!O12 -> 0.177 | I10: =Calcs!P12 -> 0.179 | J10: =Calcs!Q12 -> 0.19 | K10: =Calcs!R12 -> 0.146 | ... P10: =Calcs!W12 -> 0.109
A11: ENDTABLE
A12: ;
A13: TABLE T24N_2025BaseFanPwrIdx
A14: ; | D14: 3a – SZAC | E14: 3b – SZHP (no furnace) | F14: 3c – SZDFHP (with furnace) | G14: 7a – SZVAVAC | H14: 7b – SZVAVHP | I14: 7c – SZVAVDFHP (with furnace) | J14: 5 – PVAV | K14: 6 – VAV | L14: 9 – HEATVENT | M14: 13a - BKICHMAU | N14: 13b - PKITCHMAU | O14: 14 - 4PSZVAV | P14: 14 - 4PSZVAV | Q14: 15 - PVAVAWHP
C15: FlowCap | D15: Sys3a | E15: Sys3b | F15: Sys3c | G15: Sys7a | H15: Sys7b | I15: Sys7c | J15: Sys5 | K15: Sys6 | L15: Sys9 | M15: Sys13a | N15: Sys13b | O15: Sys14s | P15: Sys14m | Q15: Sys15
C16: <=5000 | D16: =Calcs!K15 -> 0.8 | E16: =Calcs!L15 -> 0.742 | F16: =Calcs!M15 -> 0.8 | G16: =Calcs!N15 -> 0.8 | H16: =Calcs!O15 -> 0.742 | I16: =Calcs!P15 -> 0.8 | J16: =Calcs!Q15 -> 0.978 | K16: =Calcs!R15 -> 0.978 | ... Q16: =Calcs!X15 -> 0.978
C17: <=10000 | D17: =Calcs!K16 -> 0.78 | E17: =Calcs!L16 -> 0.72 | F17: =Calcs!M16 -> 0.78 | G17: =Calcs!N16 -> 0.78 | H17: =Calcs!O16 -> 0.72 | I17: =Calcs!P16 -> 0.78 | J17: =Calcs!Q16 -> 1.013 | K17: =Calcs!R16 -> 1.013 | ... Q17: =Calcs!X16 -> 1.013
C18: >10000 | D18: =Calcs!K17 -> 0.748 | E18: =Calcs!L17 -> 0.676 | F18: =Calcs!M17 -> 0.748 | G18: =Calcs!N17 -> 0.748 | H18: =Calcs!O17 -> 0.676 | I18: =Calcs!P17 -> 0.748 | J18: =Calcs!Q17 -> 0.946 | K18: =Calcs!R17 -> 0.946 | ... Q18: =Calcs!X17 -> 0.946
A19: ENDTABLE
A20: ;
A21: TABLE T24N_2025AddBaseFanPwrIdxForEAA
A22: ; | D22: MZ-VAV (Systems 5, 6, 14, and 15) | E22: All other (Systems 1, 3, 7, and 9)
C23: FlowCap | D23: MZVAV | E23: AllOther
C24: <=5000 | D24: 0.205 | E24: 0.209
C25: <=10000 | D25: 0.174 | E25: 0.182
C26: >10000 | D26: 0.159 | E26: 0.162
A27: ENDTABLE
